[2016-10-13 14:22:16 +0000] [9286] [INFO] Starting gunicorn 19.6.0
[2016-10-13 14:22:16 +0000] [9286] [ERROR] Connection in use: ('0.0.0.0', 5000)
[2016-10-13 14:22:16 +0000] [9286] [ERROR] Retrying in 1 second.
[2016-10-13 14:22:17 +0000] [9286] [ERROR] Connection in use: ('0.0.0.0', 5000)
[2016-10-13 14:22:17 +0000] [9286] [ERROR] Retrying in 1 second.
[2016-10-13 14:22:18 +0000] [9286] [ERROR] Connection in use: ('0.0.0.0', 5000)
[2016-10-13 14:22:18 +0000] [9286] [ERROR] Retrying in 1 second.
[2016-10-13 14:22:19 +0000] [9286] [ERROR] Connection in use: ('0.0.0.0', 5000)
[2016-10-13 14:22:19 +0000] [9286] [ERROR] Retrying in 1 second.
[2016-10-13 14:22:20 +0000] [9286] [ERROR] Connection in use: ('0.0.0.0', 5000)
[2016-10-13 14:22:20 +0000] [9286] [ERROR] Retrying in 1 second.
[2016-10-13 14:22:21 +0000] [9286] [ERROR] Can't connect to ('0.0.0.0', 5000)
[2016-10-13 14:24:42 +0000] [9361] [INFO] Starting gunicorn 19.6.0
[2016-10-13 14:24:42 +0000] [9361] [ERROR] Connection in use: ('0.0.0.0', 5000)
[2016-10-13 14:24:42 +0000] [9361] [ERROR] Retrying in 1 second.
[2016-10-13 14:24:43 +0000] [9361] [ERROR] Connection in use: ('0.0.0.0', 5000)
[2016-10-13 14:24:43 +0000] [9361] [ERROR] Retrying in 1 second.
[2016-10-13 14:24:44 +0000] [9361] [ERROR] Connection in use: ('0.0.0.0', 5000)
[2016-10-13 14:24:44 +0000] [9361] [ERROR] Retrying in 1 second.
[2016-10-13 14:24:45 +0000] [9361] [ERROR] Connection in use: ('0.0.0.0', 5000)
[2016-10-13 14:24:45 +0000] [9361] [ERROR] Retrying in 1 second.
[2016-10-13 14:24:46 +0000] [9361] [ERROR] Connection in use: ('0.0.0.0', 5000)
[2016-10-13 14:24:46 +0000] [9361] [ERROR] Retrying in 1 second.
[2016-10-13 14:24:47 +0000] [9361] [ERROR] Can't connect to ('0.0.0.0', 5000)
[2016-10-13 14:25:57 +0000] [9419] [INFO] Starting gunicorn 19.6.0
[2016-10-13 14:25:57 +0000] [9419] [ERROR] Connection in use: ('0.0.0.0', 5000)
[2016-10-13 14:25:57 +0000] [9419] [ERROR] Retrying in 1 second.
[2016-10-13 14:25:58 +0000] [9419] [ERROR] Connection in use: ('0.0.0.0', 5000)
[2016-10-13 14:25:58 +0000] [9419] [ERROR] Retrying in 1 second.
[2016-10-13 14:25:59 +0000] [9419] [ERROR] Connection in use: ('0.0.0.0', 5000)
[2016-10-13 14:25:59 +0000] [9419] [ERROR] Retrying in 1 second.
[2016-10-13 14:26:00 +0000] [9419] [ERROR] Connection in use: ('0.0.0.0', 5000)
[2016-10-13 14:26:00 +0000] [9419] [ERROR] Retrying in 1 second.
[2016-10-13 14:26:01 +0000] [9419] [ERROR] Connection in use: ('0.0.0.0', 5000)
[2016-10-13 14:26:01 +0000] [9419] [ERROR] Retrying in 1 second.
[2016-10-13 14:26:02 +0000] [9419] [ERROR] Can't connect to ('0.0.0.0', 5000)
[2016-10-13 14:32:02 +0000] [9592] [INFO] Starting gunicorn 19.6.0
[2016-10-13 14:32:02 +0000] [9592] [ERROR] Connection in use: ('0.0.0.0', 5000)
[2016-10-13 14:32:02 +0000] [9592] [ERROR] Retrying in 1 second.
[2016-10-13 14:32:03 +0000] [9592] [ERROR] Connection in use: ('0.0.0.0', 5000)
[2016-10-13 14:32:03 +0000] [9592] [ERROR] Retrying in 1 second.
[2016-10-13 14:32:04 +0000] [9592] [ERROR] Connection in use: ('0.0.0.0', 5000)
[2016-10-13 14:32:04 +0000] [9592] [ERROR] Retrying in 1 second.
[2016-10-13 14:32:05 +0000] [9592] [ERROR] Connection in use: ('0.0.0.0', 5000)
[2016-10-13 14:32:05 +0000] [9592] [ERROR] Retrying in 1 second.
[2016-10-13 14:32:06 +0000] [9592] [ERROR] Connection in use: ('0.0.0.0', 5000)
[2016-10-13 14:32:06 +0000] [9592] [ERROR] Retrying in 1 second.
[2016-10-13 14:32:07 +0000] [9592] [ERROR] Can't connect to ('0.0.0.0', 5000)
[2016-10-13 14:41:13 +0000] [9936] [INFO] Starting gunicorn 19.6.0
[2016-10-13 14:41:13 +0000] [9936] [ERROR] Connection in use: ('0.0.0.0', 5000)
[2016-10-13 14:41:13 +0000] [9936] [ERROR] Retrying in 1 second.
[2016-10-13 14:41:14 +0000] [9936] [ERROR] Connection in use: ('0.0.0.0', 5000)
[2016-10-13 14:41:14 +0000] [9936] [ERROR] Retrying in 1 second.
[2016-10-13 14:41:15 +0000] [9936] [ERROR] Connection in use: ('0.0.0.0', 5000)
[2016-10-13 14:41:15 +0000] [9936] [ERROR] Retrying in 1 second.
[2016-10-13 14:41:16 +0000] [9936] [ERROR] Connection in use: ('0.0.0.0', 5000)
[2016-10-13 14:41:16 +0000] [9936] [ERROR] Retrying in 1 second.
[2016-10-13 14:41:17 +0000] [9936] [ERROR] Connection in use: ('0.0.0.0', 5000)
[2016-10-13 14:41:17 +0000] [9936] [ERROR] Retrying in 1 second.
[2016-10-13 14:41:18 +0000] [9936] [ERROR] Can't connect to ('0.0.0.0', 5000)
[2016-10-13 14:45:36 +0000] [10054] [INFO] Starting gunicorn 19.6.0
[2016-10-13 14:45:36 +0000] [10054] [ERROR] Connection in use: ('0.0.0.0', 5000)
[2016-10-13 14:45:36 +0000] [10054] [ERROR] Retrying in 1 second.
[2016-10-13 14:45:37 +0000] [10054] [ERROR] Connection in use: ('0.0.0.0', 5000)
[2016-10-13 14:45:37 +0000] [10054] [ERROR] Retrying in 1 second.
[2016-10-13 14:45:38 +0000] [10054] [ERROR] Connection in use: ('0.0.0.0', 5000)
[2016-10-13 14:45:38 +0000] [10054] [ERROR] Retrying in 1 second.
[2016-10-13 14:45:39 +0000] [10054] [ERROR] Connection in use: ('0.0.0.0', 5000)
[2016-10-13 14:45:39 +0000] [10054] [ERROR] Retrying in 1 second.
[2016-10-13 14:45:40 +0000] [10054] [ERROR] Connection in use: ('0.0.0.0', 5000)
[2016-10-13 14:45:40 +0000] [10054] [ERROR] Retrying in 1 second.
[2016-10-13 14:45:41 +0000] [10054] [ERROR] Can't connect to ('0.0.0.0', 5000)
[2016-10-13 15:06:36 +0000] [3357] [INFO] Starting gunicorn 19.6.0
[2016-10-13 15:06:36 +0000] [3357] [INFO] Listening at: http://0.0.0.0:5000 (3357)
[2016-10-13 15:06:36 +0000] [3357] [INFO] Using worker: sync
[2016-10-13 15:06:36 +0000] [3364] [INFO] Booting worker with pid: 3364
[2016-10-13 15:06:36 +0000] [3365] [INFO] Booting worker with pid: 3365
[2016-10-13 15:06:36 +0000] [3366] [INFO] Booting worker with pid: 3366
[2016-10-13 15:06:36 +0000] [3367] [INFO] Booting worker with pid: 3367
[2016-10-13 16:20:23 +0000] [3357] [INFO] Handling signal: term
[2016-10-13 16:20:23 +0000] [3364] [INFO] Worker exiting (pid: 3364)
[2016-10-13 16:20:23 +0000] [3365] [INFO] Worker exiting (pid: 3365)
[2016-10-13 16:20:23 +0000] [3366] [INFO] Worker exiting (pid: 3366)
[2016-10-13 16:20:23 +0000] [3367] [INFO] Worker exiting (pid: 3367)
[2016-10-13 16:20:23 +0000] [3357] [INFO] Shutting down: Master
[2016-10-13 16:20:36 +0000] [5217] [INFO] Starting gunicorn 19.6.0
[2016-10-13 16:20:36 +0000] [5217] [INFO] Listening at: http://0.0.0.0:5000 (5217)
[2016-10-13 16:20:36 +0000] [5217] [INFO] Using worker: sync
[2016-10-13 16:20:36 +0000] [5226] [INFO] Booting worker with pid: 5226
[2016-10-13 16:20:36 +0000] [5227] [INFO] Booting worker with pid: 5227
[2016-10-13 16:20:36 +0000] [5232] [INFO] Booting worker with pid: 5232
[2016-10-13 16:20:36 +0000] [5235] [INFO] Booting worker with pid: 5235
[2016-10-13 16:21:27 +0000] [5217] [CRITICAL] WORKER TIMEOUT (pid:5227)
[2016-10-13 16:21:27 +0000] [5217] [CRITICAL] WORKER TIMEOUT (pid:5235)
[2016-10-13 16:21:27 +0000] [5227] [INFO] Worker exiting (pid: 5227)
[2016-10-13 16:21:27 +0000] [5235] [INFO] Worker exiting (pid: 5235)
[2016-10-13 16:21:27 +0000] [5307] [INFO] Booting worker with pid: 5307
[2016-10-13 16:21:27 +0000] [5308] [INFO] Booting worker with pid: 5308
[2016-10-13 16:25:02 +0000] [5217] [CRITICAL] WORKER TIMEOUT (pid:5232)
[2016-10-13 16:25:02 +0000] [5217] [CRITICAL] WORKER TIMEOUT (pid:5307)
[2016-10-13 16:25:02 +0000] [5232] [INFO] Worker exiting (pid: 5232)
[2016-10-13 16:25:02 +0000] [5307] [INFO] Worker exiting (pid: 5307)
[2016-10-13 16:25:02 +0000] [5522] [INFO] Booting worker with pid: 5522
[2016-10-13 16:25:02 +0000] [5523] [INFO] Booting worker with pid: 5523
[2016-10-13 16:25:04 +0000] [5522] [ERROR] Exception in worker process
Traceback (most recent call last):
  File "/usr/local/lib/python2.7/dist-packages/gunicorn/arbiter.py", line 557, in spawn_worker
    worker.init_process()
  File "/usr/local/lib/python2.7/dist-packages/gunicorn/workers/base.py", line 126, in init_process
    self.load_wsgi()
  File "/usr/local/lib/python2.7/dist-packages/gunicorn/workers/base.py", line 136, in load_wsgi
    self.wsgi = self.app.wsgi()
  File "/usr/local/lib/python2.7/dist-packages/gunicorn/app/base.py", line 67, in wsgi
    self.callable = self.load()
  File "/usr/local/lib/python2.7/dist-packages/gunicorn/app/wsgiapp.py", line 65, in load
    return self.load_wsgiapp()
  File "/usr/local/lib/python2.7/dist-packages/gunicorn/app/wsgiapp.py", line 52, in load_wsgiapp
    return util.import_app(self.app_uri)
  File "/usr/local/lib/python2.7/dist-packages/gunicorn/util.py", line 357, in import_app
    __import__(module)
  File "/home/yuan/daily_news/flaskr/hello.py", line 4, in <module>
    from app import app
  File "/home/yuan/daily_news/flaskr/app/__init__.py", line 5, in <module>
    from app import view
  File "/home/yuan/daily_news/flaskr/app/view.py", line 7, in <module>
    conn = MySQLdb.connect(host='127.0.0.1', user='root', passwd='111111', db='testerhome', charset='utf8')
  File "build/bdist.linux-x86_64/egg/MySQLdb/__init__.py", line 81, in Connect
    return Connection(*args, **kwargs)
  File "build/bdist.linux-x86_64/egg/MySQLdb/connections.py", line 193, in __init__
    super(Connection, self).__init__(*args, **kwargs2)
OperationalError: (2003, "Can't connect to MySQL server on '127.0.0.1' (111)")
[2016-10-13 16:25:04 +0000] [5523] [ERROR] Exception in worker process
Traceback (most recent call last):
  File "/usr/local/lib/python2.7/dist-packages/gunicorn/arbiter.py", line 557, in spawn_worker
    worker.init_process()
  File "/usr/local/lib/python2.7/dist-packages/gunicorn/workers/base.py", line 126, in init_process
    self.load_wsgi()
  File "/usr/local/lib/python2.7/dist-packages/gunicorn/workers/base.py", line 136, in load_wsgi
    self.wsgi = self.app.wsgi()
  File "/usr/local/lib/python2.7/dist-packages/gunicorn/app/base.py", line 67, in wsgi
    self.callable = self.load()
  File "/usr/local/lib/python2.7/dist-packages/gunicorn/app/wsgiapp.py", line 65, in load
    return self.load_wsgiapp()
  File "/usr/local/lib/python2.7/dist-packages/gunicorn/app/wsgiapp.py", line 52, in load_wsgiapp
    return util.import_app(self.app_uri)
  File "/usr/local/lib/python2.7/dist-packages/gunicorn/util.py", line 357, in import_app
    __import__(module)
  File "/home/yuan/daily_news/flaskr/hello.py", line 4, in <module>
    from app import app
  File "/home/yuan/daily_news/flaskr/app/__init__.py", line 5, in <module>
    from app import view
  File "/home/yuan/daily_news/flaskr/app/view.py", line 7, in <module>
    conn = MySQLdb.connect(host='127.0.0.1', user='root', passwd='111111', db='testerhome', charset='utf8')
  File "build/bdist.linux-x86_64/egg/MySQLdb/__init__.py", line 81, in Connect
    return Connection(*args, **kwargs)
  File "build/bdist.linux-x86_64/egg/MySQLdb/connections.py", line 193, in __init__
    super(Connection, self).__init__(*args, **kwargs2)
OperationalError: (2003, "Can't connect to MySQL server on '127.0.0.1' (111)")
[2016-10-13 16:25:04 +0000] [5522] [INFO] Worker exiting (pid: 5522)
[2016-10-13 16:25:04 +0000] [5523] [INFO] Worker exiting (pid: 5523)
[2016-10-13 16:25:04 +0000] [5226] [INFO] Worker exiting (pid: 5226)
[2016-10-13 16:25:04 +0000] [5308] [INFO] Worker exiting (pid: 5308)
Traceback (most recent call last):
  File "/usr/local/bin/gunicorn", line 11, in <module>
    sys.exit(run())
  File "/usr/local/lib/python2.7/dist-packages/gunicorn/app/wsgiapp.py", line 74, in run
    WSGIApplication("%(prog)s [OPTIONS] [APP_MODULE]").run()
  File "/usr/local/lib/python2.7/dist-packages/gunicorn/app/base.py", line 192, in run
    super(Application, self).run()
  File "/usr/local/lib/python2.7/dist-packages/gunicorn/app/base.py", line 72, in run
    Arbiter(self).run()
  File "/usr/local/lib/python2.7/dist-packages/gunicorn/arbiter.py", line 218, in run
    self.halt(reason=inst.reason, exit_status=inst.exit_status)
  File "/usr/local/lib/python2.7/dist-packages/gunicorn/arbiter.py", line 331, in halt
    self.stop()
  File "/usr/local/lib/python2.7/dist-packages/gunicorn/arbiter.py", line 381, in stop
    time.sleep(0.1)
  File "/usr/local/lib/python2.7/dist-packages/gunicorn/arbiter.py", line 231, in handle_chld
    self.reap_workers()
  File "/usr/local/lib/python2.7/dist-packages/gunicorn/arbiter.py", line 506, in reap_workers
    raise HaltServer(reason, self.WORKER_BOOT_ERROR)
gunicorn.errors.HaltServer: <HaltServer 'Worker failed to boot.' 3>
[2016-10-13 16:30:20 +0000] [3326] [INFO] Starting gunicorn 19.6.0
[2016-10-13 16:30:20 +0000] [3326] [INFO] Listening at: http://0.0.0.0:5000 (3326)
[2016-10-13 16:30:20 +0000] [3326] [INFO] Using worker: sync
[2016-10-13 16:30:20 +0000] [3331] [INFO] Booting worker with pid: 3331
[2016-10-13 16:30:20 +0000] [3332] [INFO] Booting worker with pid: 3332
[2016-10-13 16:30:20 +0000] [3333] [INFO] Booting worker with pid: 3333
[2016-10-13 16:30:20 +0000] [3334] [INFO] Booting worker with pid: 3334
[2016-10-13 16:33:18 +0000] [3563] [INFO] Starting gunicorn 19.6.0
[2016-10-13 16:33:18 +0000] [3563] [ERROR] Connection in use: ('0.0.0.0', 5000)
[2016-10-13 16:33:18 +0000] [3563] [ERROR] Retrying in 1 second.
[2016-10-13 16:33:19 +0000] [3563] [ERROR] Connection in use: ('0.0.0.0', 5000)
[2016-10-13 16:33:19 +0000] [3563] [ERROR] Retrying in 1 second.
[2016-10-13 16:33:20 +0000] [3563] [ERROR] Connection in use: ('0.0.0.0', 5000)
[2016-10-13 16:33:20 +0000] [3563] [ERROR] Retrying in 1 second.
[2016-10-13 16:33:21 +0000] [3563] [ERROR] Connection in use: ('0.0.0.0', 5000)
[2016-10-13 16:33:21 +0000] [3563] [ERROR] Retrying in 1 second.
[2016-10-13 16:33:22 +0000] [3563] [ERROR] Connection in use: ('0.0.0.0', 5000)
[2016-10-13 16:33:22 +0000] [3563] [ERROR] Retrying in 1 second.
[2016-10-13 16:33:23 +0000] [3563] [ERROR] Can't connect to ('0.0.0.0', 5000)
[2016-10-13 16:35:35 +0000] [3691] [INFO] Starting gunicorn 19.6.0
[2016-10-13 16:35:35 +0000] [3691] [INFO] Listening at: http://0.0.0.0:5000 (3691)
[2016-10-13 16:35:35 +0000] [3691] [INFO] Using worker: sync
[2016-10-13 16:35:35 +0000] [3696] [INFO] Booting worker with pid: 3696
[2016-10-13 16:35:35 +0000] [3701] [INFO] Booting worker with pid: 3701
[2016-10-13 16:35:35 +0000] [3706] [INFO] Booting worker with pid: 3706
[2016-10-13 16:35:35 +0000] [3709] [INFO] Booting worker with pid: 3709
[2016-10-13 16:35:37,623] ERROR in app: Exception on /cnblog [GET]
Traceback (most recent call last):
  File "/usr/local/lib/python2.7/dist-packages/flask/app.py", line 1988, in wsgi_app
    response = self.full_dispatch_request()
  File "/usr/local/lib/python2.7/dist-packages/flask/app.py", line 1641, in full_dispatch_request
    rv = self.handle_user_exception(e)
  File "/usr/local/lib/python2.7/dist-packages/flask_restful/__init__.py", line 271, in error_router
    return original_handler(e)
  File "/usr/local/lib/python2.7/dist-packages/flask/app.py", line 1544, in handle_user_exception
    reraise(exc_type, exc_value, tb)
  File "/usr/local/lib/python2.7/dist-packages/flask/app.py", line 1639, in full_dispatch_request
    rv = self.dispatch_request()
  File "/usr/local/lib/python2.7/dist-packages/flask/app.py", line 1625, in dispatch_request
    return self.view_functions[rule.endpoint](**req.view_args)
  File "/home/yuan/daily_news/flaskr/app/view.py", line 37, in cnblog
    info['id'] = response['id']
TypeError: string indices must be integers, not str
[2016-10-13 16:36:03 +0000] [3730] [INFO] Starting gunicorn 19.6.0
[2016-10-13 16:36:03 +0000] [3730] [ERROR] Connection in use: ('0.0.0.0', 5000)
[2016-10-13 16:36:03 +0000] [3730] [ERROR] Retrying in 1 second.
[2016-10-13 16:36:04 +0000] [3730] [ERROR] Connection in use: ('0.0.0.0', 5000)
[2016-10-13 16:36:04 +0000] [3730] [ERROR] Retrying in 1 second.
[2016-10-13 16:36:05 +0000] [3730] [ERROR] Connection in use: ('0.0.0.0', 5000)
[2016-10-13 16:36:05 +0000] [3730] [ERROR] Retrying in 1 second.
[2016-10-13 16:36:06 +0000] [3730] [ERROR] Connection in use: ('0.0.0.0', 5000)
[2016-10-13 16:36:06 +0000] [3730] [ERROR] Retrying in 1 second.
[2016-10-13 16:36:07 +0000] [3730] [ERROR] Connection in use: ('0.0.0.0', 5000)
[2016-10-13 16:36:07 +0000] [3730] [ERROR] Retrying in 1 second.
[2016-10-13 16:36:08 +0000] [3730] [ERROR] Can't connect to ('0.0.0.0', 5000)
[2016-10-13 16:38:55 +0000] [3869] [INFO] Starting gunicorn 19.6.0
[2016-10-13 16:38:55 +0000] [3869] [INFO] Listening at: http://0.0.0.0:5000 (3869)
[2016-10-13 16:38:55 +0000] [3869] [INFO] Using worker: sync
[2016-10-13 16:38:55 +0000] [3874] [INFO] Booting worker with pid: 3874
[2016-10-13 16:38:55 +0000] [3877] [INFO] Booting worker with pid: 3877
[2016-10-13 16:38:55 +0000] [3879] [INFO] Booting worker with pid: 3879
[2016-10-13 16:38:55 +0000] [3885] [INFO] Booting worker with pid: 3885
[2016-10-13 16:40:45 +0000] [3923] [INFO] Starting gunicorn 19.6.0
[2016-10-13 16:40:45 +0000] [3923] [ERROR] Connection in use: ('0.0.0.0', 5000)
[2016-10-13 16:40:45 +0000] [3923] [ERROR] Retrying in 1 second.
[2016-10-13 16:40:46 +0000] [3923] [ERROR] Connection in use: ('0.0.0.0', 5000)
[2016-10-13 16:40:46 +0000] [3923] [ERROR] Retrying in 1 second.
[2016-10-13 16:40:47 +0000] [3923] [ERROR] Connection in use: ('0.0.0.0', 5000)
[2016-10-13 16:40:47 +0000] [3923] [ERROR] Retrying in 1 second.
[2016-10-13 16:40:48 +0000] [3923] [ERROR] Connection in use: ('0.0.0.0', 5000)
[2016-10-13 16:40:48 +0000] [3923] [ERROR] Retrying in 1 second.
[2016-10-13 16:40:49 +0000] [3923] [ERROR] Connection in use: ('0.0.0.0', 5000)
[2016-10-13 16:40:49 +0000] [3923] [ERROR] Retrying in 1 second.
[2016-10-13 16:40:50 +0000] [3923] [ERROR] Can't connect to ('0.0.0.0', 5000)
[2016-10-13 16:40:51 +0000] [3953] [INFO] Starting gunicorn 19.6.0
[2016-10-13 16:40:51 +0000] [3953] [ERROR] Connection in use: ('0.0.0.0', 5000)
[2016-10-13 16:40:51 +0000] [3953] [ERROR] Retrying in 1 second.
[2016-10-13 16:40:52 +0000] [3953] [ERROR] Connection in use: ('0.0.0.0', 5000)
[2016-10-13 16:40:52 +0000] [3953] [ERROR] Retrying in 1 second.
[2016-10-13 16:40:53 +0000] [3953] [ERROR] Connection in use: ('0.0.0.0', 5000)
[2016-10-13 16:40:53 +0000] [3953] [ERROR] Retrying in 1 second.
[2016-10-13 16:40:54 +0000] [3953] [INFO] Listening at: http://0.0.0.0:5000 (3953)
[2016-10-13 16:40:54 +0000] [3953] [INFO] Using worker: sync
[2016-10-13 16:40:54 +0000] [3963] [INFO] Booting worker with pid: 3963
[2016-10-13 16:40:54 +0000] [3966] [INFO] Booting worker with pid: 3966
[2016-10-13 16:40:54 +0000] [3971] [INFO] Booting worker with pid: 3971
[2016-10-13 16:40:54 +0000] [3972] [INFO] Booting worker with pid: 3972
[2016-10-13 16:49:29 +0000] [3953] [CRITICAL] WORKER TIMEOUT (pid:3963)
[2016-10-13 16:49:29 +0000] [3953] [CRITICAL] WORKER TIMEOUT (pid:3971)
[2016-10-13 16:49:29 +0000] [3963] [INFO] Worker exiting (pid: 3963)
[2016-10-13 16:49:29 +0000] [3971] [INFO] Worker exiting (pid: 3971)
[2016-10-13 16:49:29 +0000] [3953] [CRITICAL] WORKER TIMEOUT (pid:3966)
[2016-10-13 16:49:29 +0000] [3966] [INFO] Worker exiting (pid: 3966)
[2016-10-13 16:49:29 +0000] [4412] [INFO] Booting worker with pid: 4412
[2016-10-13 16:49:29 +0000] [4413] [INFO] Booting worker with pid: 4413
[2016-10-13 16:49:29 +0000] [4418] [INFO] Booting worker with pid: 4418
[2016-10-13 16:50:33 +0000] [3953] [CRITICAL] WORKER TIMEOUT (pid:4412)
[2016-10-13 16:50:33 +0000] [3953] [CRITICAL] WORKER TIMEOUT (pid:4413)
[2016-10-13 16:50:33 +0000] [4413] [INFO] Worker exiting (pid: 4413)
[2016-10-13 16:50:33 +0000] [4412] [INFO] Worker exiting (pid: 4412)
[2016-10-13 16:50:33 +0000] [4470] [INFO] Booting worker with pid: 4470
[2016-10-13 16:50:33 +0000] [4471] [INFO] Booting worker with pid: 4471
[2016-10-13 17:48:09 +0000] [4470] [INFO] Worker exiting (pid: 4470)
[2016-10-13 17:48:09 +0000] [4471] [INFO] Worker exiting (pid: 4471)
[2016-10-13 17:48:09 +0000] [3972] [INFO] Worker exiting (pid: 3972)
[2016-10-13 17:48:09 +0000] [3953] [INFO] Handling signal: term
[2016-10-13 17:48:09 +0000] [4418] [INFO] Worker exiting (pid: 4418)
[2016-10-13 17:54:55 +0000] [3142] [INFO] Starting gunicorn 19.6.0
[2016-10-13 17:54:55 +0000] [3142] [INFO] Listening at: http://0.0.0.0:5000 (3142)
[2016-10-13 17:54:55 +0000] [3142] [INFO] Using worker: sync
[2016-10-13 17:54:55 +0000] [3152] [INFO] Booting worker with pid: 3152
[2016-10-13 17:54:55 +0000] [3156] [INFO] Booting worker with pid: 3156
[2016-10-13 17:54:55 +0000] [3157] [INFO] Booting worker with pid: 3157
[2016-10-13 17:54:55 +0000] [3158] [INFO] Booting worker with pid: 3158
[2016-10-14 13:03:16,199] ERROR in app: Exception on / [GET]
Traceback (most recent call last):
  File "/usr/local/lib/python2.7/dist-packages/flask/app.py", line 1988, in wsgi_app
    response = self.full_dispatch_request()
  File "/usr/local/lib/python2.7/dist-packages/flask/app.py", line 1641, in full_dispatch_request
    rv = self.handle_user_exception(e)
  File "/usr/local/lib/python2.7/dist-packages/flask/app.py", line 1544, in handle_user_exception
    reraise(exc_type, exc_value, tb)
  File "/usr/local/lib/python2.7/dist-packages/flask/app.py", line 1639, in full_dispatch_request
    rv = self.dispatch_request()
  File "/usr/local/lib/python2.7/dist-packages/flask/app.py", line 1625, in dispatch_request
    return self.view_functions[rule.endpoint](**req.view_args)
  File "/home/yuan/daily_news/flaskr/app/view.py", line 16, in info
    info['id'] = response['id']
TypeError: string indices must be integers
[2016-10-14 13:03:37,313] ERROR in app: Exception on / [GET]
Traceback (most recent call last):
  File "/usr/local/lib/python2.7/dist-packages/flask/app.py", line 1988, in wsgi_app
    response = self.full_dispatch_request()
  File "/usr/local/lib/python2.7/dist-packages/flask/app.py", line 1641, in full_dispatch_request
    rv = self.handle_user_exception(e)
  File "/usr/local/lib/python2.7/dist-packages/flask/app.py", line 1544, in handle_user_exception
    reraise(exc_type, exc_value, tb)
  File "/usr/local/lib/python2.7/dist-packages/flask/app.py", line 1639, in full_dispatch_request
    rv = self.dispatch_request()
  File "/usr/local/lib/python2.7/dist-packages/flask/app.py", line 1625, in dispatch_request
    return self.view_functions[rule.endpoint](**req.view_args)
  File "/home/yuan/daily_news/flaskr/app/view.py", line 16, in info
    info['id'] = response['id']
TypeError: string indices must be integers
[2016-10-14 13:04:07 +0000] [3142] [CRITICAL] WORKER TIMEOUT (pid:3152)
[2016-10-14 13:04:07 +0000] [3142] [CRITICAL] WORKER TIMEOUT (pid:3157)
[2016-10-14 13:04:07 +0000] [3152] [INFO] Worker exiting (pid: 3152)
[2016-10-14 13:04:07 +0000] [3157] [INFO] Worker exiting (pid: 3157)
[2016-10-14 13:04:07 +0000] [4758] [INFO] Booting worker with pid: 4758
[2016-10-14 13:04:07 +0000] [4759] [INFO] Booting worker with pid: 4759
[2016-10-14 13:07:19 +0000] [4759] [INFO] Worker exiting (pid: 4759)
[2016-10-14 13:07:19 +0000] [4758] [INFO] Worker exiting (pid: 4758)
[2016-10-14 13:07:19 +0000] [3156] [INFO] Worker exiting (pid: 3156)
[2016-10-14 13:07:19 +0000] [3158] [INFO] Worker exiting (pid: 3158)
[2016-10-14 13:07:19 +0000] [3142] [INFO] Handling signal: term
[2016-10-14 13:11:30 +0000] [2693] [INFO] Starting gunicorn 19.6.0
[2016-10-14 13:11:30 +0000] [2693] [INFO] Listening at: http://0.0.0.0:5000 (2693)
[2016-10-14 13:11:30 +0000] [2693] [INFO] Using worker: sync
[2016-10-14 13:11:30 +0000] [2703] [INFO] Booting worker with pid: 2703
[2016-10-14 13:11:30 +0000] [2704] [INFO] Booting worker with pid: 2704
[2016-10-14 13:11:30 +0000] [2705] [INFO] Booting worker with pid: 2705
[2016-10-14 13:11:30 +0000] [2707] [INFO] Booting worker with pid: 2707
[2016-10-14 14:20:54 +0000] [2693] [CRITICAL] WORKER TIMEOUT (pid:2705)
[2016-10-14 14:20:54 +0000] [2693] [CRITICAL] WORKER TIMEOUT (pid:2707)
[2016-10-14 14:20:54 +0000] [2705] [INFO] Worker exiting (pid: 2705)
[2016-10-14 14:20:54 +0000] [2707] [INFO] Worker exiting (pid: 2707)
[2016-10-14 14:20:55 +0000] [4108] [INFO] Booting worker with pid: 4108
[2016-10-14 14:20:55 +0000] [4109] [INFO] Booting worker with pid: 4109
[2016-10-14 14:45:23 +0000] [2693] [CRITICAL] WORKER TIMEOUT (pid:4108)
[2016-10-14 14:45:23 +0000] [2693] [CRITICAL] WORKER TIMEOUT (pid:2703)
[2016-10-14 14:45:23 +0000] [4108] [INFO] Worker exiting (pid: 4108)
[2016-10-14 14:45:23 +0000] [2703] [INFO] Worker exiting (pid: 2703)
[2016-10-14 14:45:24 +0000] [4710] [INFO] Booting worker with pid: 4710
[2016-10-14 14:45:24 +0000] [4711] [INFO] Booting worker with pid: 4711
[2016-10-14 14:46:58 +0000] [2693] [CRITICAL] WORKER TIMEOUT (pid:4711)
[2016-10-14 14:46:58 +0000] [4711] [INFO] Worker exiting (pid: 4711)
[2016-10-14 14:46:58 +0000] [4760] [INFO] Booting worker with pid: 4760
[2016-10-14 16:00:08,588] ERROR in app: Exception on /bole [GET]
Traceback (most recent call last):
  File "/usr/local/lib/python2.7/dist-packages/flask/app.py", line 1988, in wsgi_app
    response = self.full_dispatch_request()
  File "/usr/local/lib/python2.7/dist-packages/flask/app.py", line 1641, in full_dispatch_request
    rv = self.handle_user_exception(e)
  File "/usr/local/lib/python2.7/dist-packages/flask/app.py", line 1544, in handle_user_exception
    reraise(exc_type, exc_value, tb)
  File "/usr/local/lib/python2.7/dist-packages/flask/app.py", line 1639, in full_dispatch_request
    rv = self.dispatch_request()
  File "/usr/local/lib/python2.7/dist-packages/flask/app.py", line 1625, in dispatch_request
    return self.view_functions[rule.endpoint](**req.view_args)
  File "/home/yuan/daily_news/flaskr/app/view.py", line 53, in bole
    feed_response = json.loads(requests.get(server_url + '/bole').content)
  File "/usr/lib/python2.7/dist-packages/requests/api.py", line 55, in get
    return request('get', url, **kwargs)
  File "/usr/lib/python2.7/dist-packages/requests/api.py", line 44, in request
    return session.request(method=method, url=url, **kwargs)
  File "/usr/lib/python2.7/dist-packages/requests/sessions.py", line 421, in request
    prep = self.prepare_request(req)
  File "/usr/lib/python2.7/dist-packages/requests/sessions.py", line 359, in prepare_request
    hooks=merge_hooks(request.hooks, self.hooks),
  File "/usr/lib/python2.7/dist-packages/requests/models.py", line 287, in prepare
    self.prepare_url(url, params)
  File "/usr/lib/python2.7/dist-packages/requests/models.py", line 334, in prepare_url
    scheme, auth, host, port, path, query, fragment = parse_url(url)
  File "/usr/lib/python2.7/dist-packages/urllib3/util.py", line 390, in parse_url
    raise LocationParseError("Failed to parse: %s" % url)
LocationParseError: Failed to parse: Failed to parse: 127.0.0.1:5001bole
[2016-10-14 16:00:34 +0000] [6410] [INFO] Starting gunicorn 19.6.0
[2016-10-14 16:00:34 +0000] [6410] [ERROR] Connection in use: ('0.0.0.0', 5000)
[2016-10-14 16:00:34 +0000] [6410] [ERROR] Retrying in 1 second.
[2016-10-14 16:00:35 +0000] [6410] [ERROR] Connection in use: ('0.0.0.0', 5000)
[2016-10-14 16:00:35 +0000] [6410] [ERROR] Retrying in 1 second.
[2016-10-14 16:00:36 +0000] [6410] [ERROR] Connection in use: ('0.0.0.0', 5000)
[2016-10-14 16:00:36 +0000] [6410] [ERROR] Retrying in 1 second.
[2016-10-14 16:00:37 +0000] [6410] [ERROR] Connection in use: ('0.0.0.0', 5000)
[2016-10-14 16:00:37 +0000] [6410] [ERROR] Retrying in 1 second.
[2016-10-14 16:00:38 +0000] [6410] [ERROR] Connection in use: ('0.0.0.0', 5000)
[2016-10-14 16:00:38 +0000] [6410] [ERROR] Retrying in 1 second.
[2016-10-14 16:00:39 +0000] [6410] [ERROR] Can't connect to ('0.0.0.0', 5000)
[2016-10-14 16:00:39 +0000] [6421] [INFO] Starting gunicorn 19.6.0
[2016-10-14 16:00:39 +0000] [6421] [ERROR] Connection in use: ('0.0.0.0', 5000)
[2016-10-14 16:00:39 +0000] [6421] [ERROR] Retrying in 1 second.
[2016-10-14 16:00:40 +0000] [6421] [ERROR] Connection in use: ('0.0.0.0', 5000)
[2016-10-14 16:00:40 +0000] [6421] [ERROR] Retrying in 1 second.
[2016-10-14 16:00:41 +0000] [6421] [INFO] Listening at: http://0.0.0.0:5000 (6421)
[2016-10-14 16:00:41 +0000] [6421] [INFO] Using worker: sync
[2016-10-14 16:00:41 +0000] [6434] [INFO] Booting worker with pid: 6434
[2016-10-14 16:00:41 +0000] [6436] [INFO] Booting worker with pid: 6436
[2016-10-14 16:00:41 +0000] [6437] [INFO] Booting worker with pid: 6437
[2016-10-14 16:00:42 +0000] [6438] [INFO] Booting worker with pid: 6438
